Workbook

Sheet Scope1
T1: Emission Factors
A2: Month | B2: Octane for Vehicle (Taka) | C2: Price per liter (Taka) | D2: Octane for Vehicle (Liter) | E2: Octane for Vehicle (Taka) | F2: Octane for Vehicle (Taka) | G2: Octane for Vehicle (Liter) | I2: Month | J2: Diesel for Generator (Taka) | K2: Price per liter (Taka) | L2: Diesel for Generator (Liter) | N2: Source | P2: Monthly Quantity (Cylinder) | Q2: Size (Kg) | R2: Gas Used in a Year (kg) | T2: Source | V2: CO2 | W2: CH4 | X2: N2O | Y2: Unit
A3: January | B3: 95940 | C3: 130 | D3: =B3/C$3 -> 738 | E3: 24080 | F3: 109 | G3: =E3/F$3 -> 220.91743 | I3: January | J3: 0 | K3: 109 | L3: =J3/K$3 -> 0 | N3: Olympia Palace | P3: 20 | Q3: 35 | R3: =P3*Q3*12 -> 8400 | T3: Gasoline (Octane) | V3: 2.272 | W3: 0.00032782 | X3: 1.96692e-05 | Y3: kg/liter
A4: February | B4: 93440 | D4: =B4/C$3 -> 718.76923 | E4: 33720 | G4: =E4/F$3 -> 309.3578 | I4: February | J4: 87200 | L4: =J4/K$3 -> 800 | N4: Shamim Canteen | P4: 15 | Q4: 12 | R4: =P4*Q4*12 -> 2160 | T4: Diesel (transport) | V4: 2.676 | W4: 0.0003612 | X4: 2.1672e-05 | Y4: kg/liter
A5: March | B5: 86950 | D5: =B5/C$3 -> 668.84615 | E5: 187250 | G5: =E5/F$3 -> 1717.8899 | I5: March | J5: 87200 | L5: =J5/K$3 -> 800 | N5: Jamal Store | P5: 15 | Q5: 12 | R5: =P5*Q5*12 -> 2160 | T5: Liquid Petroleum Gas (LPG) | V5: 1.612 | W5: 0.00037976 | X5: 2.5542e-06 | Y5: kg/liter
A6: April | B6: 95695 | D6: =B6/C$3 -> 736.11538 | E6: 230560 | G6: =E6/F$3 -> 2115.2294 | I6: April | J6: 0 | L6: =J6/K$3 -> 0 | N6: Total | Q6: =SUM(Q3:Q5) -> 59 | R6: =SUM(R3:R5) -> 12720 | T6: Diesel (stationary) | V6: 2.676 | W6: 0.0003612 | X6: 2.1672e-05 | Y6: kg/liter
A7: May | B7: 97860 | D7: =B7/C$3 -> 752.76923 | E7: 212650 | G7: =E7/F$3 -> 1950.9174 | I7: May | J7: 87200 | L7: =J7/K$3 -> 800 | T7: R410A / HFCs(Refrigerant Gas) [1] | V7: =0.5*771+0.5*3740 -> 2255.5 | Y7: kgCO2-eq/kg
A8: June | B8: 8590 | D8: =B8/C$3 -> 66.076923 | E8: 185320 | G8: =E8/F$3 -> 1700.1835 | I8: June | J8: 0 | L8: =J8/K$3 -> 0 | T8: R22/HCFC (Refrigerant Gas) [1] | V8: 1960 | Y8: kgCO2-eq/kg
A9: July | B9: 65005 | D9: =B9/C$3 -> 500.03846 | E9: 164650 | G9: =E9/F$3 -> 1510.5505 | I9: July | J9: 40000 | L9: =J9/K$3 -> 366.97248 | T9: R32/HFC (Refrigerant Gas) [2] | V9: 677 | Y9: kgCO2-eq/kg
A10: August | B10: 110278 | D10: =B10/C$3 -> 848.29231 | E10: 203667 | G10: =E10/F$3 -> 1868.5046 | I10: August | J10: 114000 | L10: =J10/K$3 -> 1045.8716 | T10: [1] The Earth's Energy Budget, Climate Feedbacks and Climate Sensitivity Supplemetary Material (7SM). https://www.ipcc.ch/report/ar6/wg1/downloads/report/IPCC_AR6_WGI_Chapter07_SM.pdf
A11: September | B11: 113240 | D11: =B11/C$3 -> 871.07692 | E11: 201527 | G11: =E11/F$3 -> 1848.8716 | I11: September | J11: 316100 | L11: =J11/K$3 -> 2900
A12: October | B12: 127290 | D12: =B12/C$3 -> 979.15385 | E12: 202125 | G12: =E12/F$3 -> 1854.3578 | I12: October | J12: 0 | L12: =J12/K$3 -> 0
A13: November | B13: 125380 | D13: =B13/C$3 -> 964.46154 | E13: 216790 | G13: =E13/F$3 -> 1988.8991 | I13: November | J13: 174400 | L13: =J13/K$3 -> 1600
A14: December | B14: 97450 | D14: =B14/C$3 -> 749.61538 | E14: 222698 | G14: =E14/F$3 -> 2043.1009 | I14: December | J14: 87200 | L14: =J14/K$3 -> 800 | T14: 2. https://doi.org/10.1016/j.rser.2017.05.216
A15: Sub Total | B15: =SUM(B3:B14) -> 1117118 | I15: Sub Total | J15: =SUM(J3:J14) -> 993300 | L15: =SUM(L3:L14) -> 9112.844
A17: GHG Emissions from University Vehicles (Gasoline and Diesel) | U17: Scope 1
A18: Month | B18: Octane for Vehicle (Liter) | C18: Gasoline (Octane) CO2 Emission Factor (kg/L) | D18: Gasoline (Octane) CH4 Emission Factor (kg/L) | E18: Gasoline (Octane) N2O Emission Factor (kg/L) | F18: Total CO2 Emission from Octane for Vehicle (ton-CO2) | G18: Total CH4 Emission from Octane for Vehicle (ton-CH4) | H18: Total N2O Emission from Octane for Vehicle (ton-CO2) | I18: Diesel for Vehicle (Litre) | J18: Diesel CO2 Emission Factor (kg/L) | K18: Diesel CH4 Emission Factor (kg/L) | L18: Diesel N2O Emission Factor (kg/L) | M18: Total CO2 Emission from Diesel for Vehicle (ton-CO2) | N18: Total CH4 Emission from Diesel for Vehicle (ton-CH4) | O18: Total N2O Emission from Diesel for Vehicle (ton-N2O) | P18: Total CO2 Emission from Vehicle (tCO2) | Q18: Total CH4 Emission from Vehicle (tCH4) | R18: Total N2O Emission from Vehicle (tN2O) | U18: Total CO2 Emission from Scope 1 (tCO2) | V18: Total CH4 Emission from Scope 1 (tCH4) | W18: Total N2O Emission from Scope 1 (tN2O)
A19: January | B19: =D3 -> 738 | C19: =V3 -> 2.272 | D19: =W3 -> 0.00032782 | E19: =X3 -> 1.96692e-05 | F19: =(B19*C$19)/(1000) -> 1.676736 | G19: =(B19*D$19)/(1000) -> 0.00024193116 | H19: =(B19*E$19)/(1000) -> 1.451587e-05 | I19: =G3 -> 220.91743 | J19: =V4 -> 2.676 | K19: =W4 -> 0.0003612 | L19: =X4 -> 2.1672e-05 | M19: =(I19*J$19)/(1000) -> 0.59117505 | N19: =(I19*K$19)/(1000) -> 7.9795376e-05 | O19: =(I19*L$19)/(1000) -> 4.7877226e-06 | P19: =(F19+M19) -> 2.267911 | Q19: =(G19+N19) -> 0.00032172654 | R19: =(H19+O19) -> 1.9303592e-05 | U19: =P31+F47+N38 -> 115.60301 | V19: =Q31+G47+O38 -> 0.01784845 | W19: =R31+H47+P38 -> 0.00081356357
A20: February | B20: =D4 -> 718.76923 | F20: =(B20*C$19)/(1000) -> 1.6330437 | G20: =(B20*D$19)/(1000) -> 0.00023562693 | H20: =(B20*E$19)/(1000) -> 1.4137616e-05 | I20: =G4 -> 309.3578 | M20: =(I20*J$19)/(1000) -> 0.82784147 | N20: =(I20*K$19)/(1000) -> 0.00011174004 | O20: =(I20*L$19)/(1000) -> 6.7044022e-06 | P20: =(F20+M20) -> 2.4608852 | Q20: =(G20+N20) -> 0.00034736697 | R20: =(H20+O20) -> 2.0842018e-05
A21: March | B21: =D5 -> 668.84615 | F21: =(B21*C$19)/(1000) -> 1.5196185 | G21: =(B21*D$19)/(1000) -> 0.00021926115 | H21: =(B21*E$19)/(1000) -> 1.3155669e-05 | I21: =G5 -> 1717.8899 | M21: =(I21*J$19)/(1000) -> 4.5970734 | N21: =(I21*K$19)/(1000) -> 0.00062050183 | O21: =(I21*L$19)/(1000) -> 3.723011e-05 | P21: =(F21+M21) -> 6.1166919 | Q21: =(G21+N21) -> 0.00083976298 | R21: =(H21+O21) -> 5.0385779e-05
A22: April | B22: =D6 -> 736.11538 | F22: =(B22*C$19)/(1000) -> 1.6724542 | G22: =(B22*D$19)/(1000) -> 0.00024131335 | H22: =(B22*E$19)/(1000) -> 1.4478801e-05 | I22: =G6 -> 2115.2294 | M22: =(I22*J$19)/(1000) -> 5.6603538 | N22: =(I22*K$19)/(1000) -> 0.00076402084 | O22: =(I22*L$19)/(1000) -> 4.5841251e-05 | P22: =(F22+M22) -> 7.3328079 | Q22: =(G22+N22) -> 0.0010053342 | R22: =(H22+O22) -> 6.0320051e-05
A23: May | B23: =D7 -> 752.76923 | F23: =(B23*C$19)/(1000) -> 1.7102917 | G23: =(B23*D$19)/(1000) -> 0.00024677281 | H23: =(B23*E$19)/(1000) -> 1.4806369e-05 | I23: =G7 -> 1950.9174 | M23: =(I23*J$19)/(1000) -> 5.220655 | N23: =(I23*K$19)/(1000) -> 0.00070467138 | O23: =(I23*L$19)/(1000) -> 4.2280283e-05 | P23: =(F23+M23) -> 6.9309467 | Q23: =(G23+N23) -> 0.00095144419 | R23: =(H23+O23) -> 5.7086651e-05
A24: June | B24: =D8 -> 66.076923 | F24: =(B24*C$19)/(1000) -> 0.15012677 | G24: =(B24*D$19)/(1000) -> 2.1661337e-05 | H24: =(B24*E$19)/(1000) -> 1.2996802e-06 | I24: =G8 -> 1700.1835 | M24: =(I24*J$19)/(1000) -> 4.549691 | N24: =(I24*K$19)/(1000) -> 0.00061410628 | O24: =(I24*L$19)/(1000) -> 3.6846377e-05 | P24: =(F24+M24) -> 4.6998178 | Q24: =(G24+N24) -> 0.00063576761 | R24: =(H24+O24) -> 3.8146057e-05
A25: July | B25: =D9 -> 500.03846 | F25: =(B25*C$19)/(1000) -> 1.1360874 | G25: =(B25*D$19)/(1000) -> 0.00016392261 | H25: =(B25*E$19)/(1000) -> 9.8353565e-06 | I25: =G9 -> 1510.5505 | M25: =(I25*J$19)/(1000) -> 4.042233 | N25: =(I25*K$19)/(1000) -> 0.00054561083 | O25: =(I25*L$19)/(1000) -> 3.273665e-05 | P25: =(F25+M25) -> 5.1783204 | Q25: =(G25+N25) -> 0.00070953343 | R25: =(H25+O25) -> 4.2572006e-05
A26: August | B26: =D10 -> 848.29231 | F26: =(B26*C$19)/(1000) -> 1.9273201 | G26: =(B26*D$19)/(1000) -> 0.00027808718 | H26: =(B26*E$19)/(1000) -> 1.6685231e-05 | I26: =G10 -> 1868.5046 | M26: =(I26*J$19)/(1000) -> 5.0001183 | N26: =(I26*K$19)/(1000) -> 0.00067490386 | O26: =(I26*L$19)/(1000) -> 4.0494231e-05 | P26: =(F26+M26) -> 6.9274384 | Q26: =(G26+N26) -> 0.00095299104 | R26: =(H26+O26) -> 5.7179462e-05
A27: September | B27: =D11 -> 871.07692 | F27: =(B27*C$19)/(1000) -> 1.9790868 | G27: =(B27*D$19)/(1000) -> 0.00028555644 | H27: =(B27*E$19)/(1000) -> 1.7133386e-05 | I27: =G11 -> 1848.8716 | M27: =(I27*J$19)/(1000) -> 4.9475803 | N27: =(I27*K$19)/(1000) -> 0.00066781241 | O27: =(I27*L$19)/(1000) -> 4.0068744e-05 | P27: =(F27+M27) -> 6.9266671 | Q27: =(G27+N27) -> 0.00095336884 | R27: =(H27+O27) -> 5.7202131e-05
A28: October | B28: =D12 -> 979.15385 | F28: =(B28*C$19)/(1000) -> 2.2246375 | G28: =(B28*D$19)/(1000) -> 0.00032098621 | H28: =(B28*E$19)/(1000) -> 1.9259173e-05 | I28: =G12 -> 1854.3578 | M28: =(I28*J$19)/(1000) -> 4.9622615 | N28: =(I28*K$19)/(1000) -> 0.00066979404 | O28: =(I28*L$19)/(1000) -> 4.0187642e-05 | P28: =(F28+M28) -> 7.186899 | Q28: =(G28+N28) -> 0.00099078025 | R28: =(H28+O28) -> 5.9446815e-05
A29: November | B29: =D13 -> 964.46154 | F29: =(B29*C$19)/(1000) -> 2.1912566 | G29: =(B29*D$19)/(1000) -> 0.00031616978 | H29: =(B29*E$19)/(1000) -> 1.8970187e-05 | I29: =G13 -> 1988.8991 | M29: =(I29*J$19)/(1000) -> 5.3222939 | N29: =(I29*K$19)/(1000) -> 0.00071839035 | O29: =(I29*L$19)/(1000) -> 4.3103421e-05 | P29: =(F29+M29) -> 7.5135506 | Q29: =(G29+N29) -> 0.0010345601 | R29: =(H29+O29) -> 6.2073608e-05
A30: December | B30: =D14 -> 749.61538 | F30: =(B30*C$19)/(1000) -> 1.7031262 | G30: =(B30*D$19)/(1000) -> 0.00024573892 | H30: =(B30*E$19)/(1000) -> 1.4744335e-05 | I30: =G14 -> 2043.1009 | M30: =(I30*J$19)/(1000) -> 5.4673381 | N30: =(I30*K$19)/(1000) -> 0.00073796805 | O30: =(I30*L$19)/(1000) -> 4.4278083e-05 | P30: =(F30+M30) -> 7.1704642 | Q30: =(G30+N30) -> 0.00098370697 | R30: =(H30+O30) -> 5.9022418e-05 | T30: CO2 | U30: CH4 | V30: N2O
A31: Sub Total | B31: =SUM(B19:B30) -> 8593.2154 | F31: =SUM(F19:F30) -> 19.523785 | G31: =SUM(G19:G30) -> 0.0028170279 | H31: =SUM(H19:H30) -> 0.00016902167 | I31: =SUM(I19:I30) -> 19128.78 | M31: =SUM(M19:M30) -> 51.188615 | N31: =SUM(N19:N30) -> 0.0069093153 | O31: =SUM(O19:O30) -> 0.00041455892 | P31: =SUM(P19:P30) -> 70.7124 | Q31: =SUM(Q19:Q30) -> 0.0097263431 | R31: =SUM(R19:R30) -> 0.00058358059 | S31: GWP | T31: 1 | U31: 27.9 | V31: 273
S32: CO2-eq (tCO2-eq) | T32: =P31*T31 -> 70.7124 | U32: =Q31*U31 -> 0.27136497 | V32: =R31*V31 -> 0.1593175
A33: GHG Emissions from Electricity Generation on Campus (Diesel) | J33: GHG Emissions from Cooking in Cafeteria (LPG) | S33: Total CO2-eq (tCO2-eq) | T33: =SUM(T32:V32) -> 71.143083
A34: Month | B34: Octane for Vehicle (Liter) | C34: Diesel CO2 Emission Factor (kg/L) | D34: Diesel CH4 Emission Factor (kg/L) | E34: Diesel N2O Emission Factor (kg/L) | F34: Total CO2 Emission from Diesel for Generator (ton-CO2) | G34: Total CO4 Emission from Diesel for Generator (ton-CH4) | H34: Total N2O Emission from Diesel for Generator (ton-N2O) | J34: Gas Used in a Year (kg) | K34: Liquefied Petroleum Gas (LPG) CO2 Emission Factor (kg/liter) | L34: Liquefied Petroleum Gas (LPG) CH4 Emission Factor (kg/liter) | M34: Liquefied Petroleum Gas (LPG) N2O Emission Factor (kg/liter) | N34: Total CO2 Emission from Caferetia (tCO2) | O34: Total CH4 Emission from Caferetia (tCH4) | P34: Total N2O Emission from Caferetia (tN2O)
A35: January | B35: =L3 -> 0 | C35: =V6 -> 2.676 | D35: =W6 -> 0.0003612 | E35: =X6 -> 2.1672e-05 | F35: =(B35*C$35)/(1000) -> 0 | G35: =(B35*D$35)/(1000) -> 0 | H35: =(B35*E$35)/(1000) -> 0 | J35: =R6 -> 12720 | K35: =V5 -> 1.612 | L35: =W5 -> 0.00037976 | M35: =X5 -> 2.5542e-06 | N35: =(J35*K$35)/(1000) -> 20.50464 | O35: =(J35*L$35)/(1000) -> 0.0048305472 | P35: =(J35*M$35)/(1000) -> 3.2489424e-05
A36: February | B36: =L4 -> 800 | F36: =(B36*C$35)/(1000) -> 2.1408 | G36: =(B36*D$35)/(1000) -> 0.00028896 | H36: =(B36*E$35)/(1000) -> 1.73376e-05
A37: March | B37: =L5 -> 800 | F37: =(B37*C$35)/(1000) -> 2.1408 | G37: =(B37*D$35)/(1000) -> 0.00028896 | H37: =(B37*E$35)/(1000) -> 1.73376e-05
A38: April | B38: =L6 -> 0 | F38: =(B38*C$35)/(1000) -> 0 | G38: =(B38*D$35)/(1000) -> 0 | H38: =(B38*E$35)/(1000) -> 0 | N38: =SUM(N35:N37) -> 20.50464 | O38: =SUM(O35:O37) -> 0.0048305472 | P38: =SUM(P35:P37) -> 3.2489424e-05 | R38: CO2 | S38: CH4 | T38: N2O
A39: May | B39: =L7 -> 800 | F39: =(B39*C$35)/(1000) -> 2.1408 | G39: =(B39*D$35)/(1000) -> 0.00028896 | H39: =(B39*E$35)/(1000) -> 1.73376e-05 | Q39: GWP | R39: 1 | S39: 27.9 | T39: 273
A40: June | B40: =L8 -> 0 | F40: =(B40*C$35)/(1000) -> 0 | G40: =(B40*D$35)/(1000) -> 0 | H40: =(B40*E$35)/(1000) -> 0 | J40: Fugitive GHG Emissions from Refrigerant in AC (Sales-based approach of GHG Protocol) | Q40: CO2-eq (tCO2-eq) | R40: =N38*R39 -> 20.50464 | S40: =O38*S39 -> 0.13477227 | T40: =P38*T39 -> 0.0088696128
A41: July | B41: =L9 -> 366.97248 | F41: =(B41*C$35)/(1000) -> 0.98201835 | G41: =(B41*D$35)/(1000) -> 0.00013255046 | H41: =(B41*E$35)/(1000) -> 7.9530275e-06 | J41: R-410A Gas Used in a Year (kg) | K41: R-410A CO2 Emission Factor (kgCO2-eq./kg) | L41: Total CO2 Emission from AC due to R-410A (tCO2-eq) | M41: R-22/HCFC-22 Gas Used in a Year (kg) | N41: R-22/HCFC-22 CO2 Emission Factor (kgCO2-eq./kg) | O41: Total CO2 Emission from AC due to R22 (tCO2-eq.) | P41: Total CO2 Emission from AC (tCO2-eq) | Q41: Total CO2-eq (tCO2-eq) | R41: =SUM(R40:T40) -> 20.648282
...

Sheet Scope2
A1: Electricity Consumption by ULAB in Year 2022 | H1: GHG (CO2-eq.) . Emission Factor (gCO2-eq./kWh) | I1: GHG CO2-eq. Emission in 2022 (ton-CO2/year)
A2: Month | B2: Meter - 1 (kWh) | D2: Meter - 2 (kWh) | F2: Sub-Total (kWh)
B4: OFFPK | C4: PK | D4: OFFPK | E4: PK | F4: OFFPK | G4: PK | H4: =C38 -> 637.86139 | I4: =(H4*$F$19)/(1000*1000) -> 454.13646
A5: January | B5: 4608 | C5: 1584 | D5: 8328 | E5: 2244 | F5: =B5+D5 -> 12936 | G5: =C5+E5 -> 3828
A6: February | B6: 7644 | C6: 1776 | D6: 9552 | E6: 2304 | F6: =B6+D6 -> 17196 | G6: =C6+E6 -> 4080 | M6: 50% implementation | N6: 100% implementation | O6: Emission
A7: March | B7: 24528 | C7: 3324 | D7: 43188 | E7: 6204 | F7: =B7+D7 -> 67716 | G7: =C7+E7 -> 9528 | L7: 66225 | M7: =F18-L7 -> 575187
A8: April | B8: 19200 | C8: 1200 | D8: 35172 | E8: 3876 | F8: =B8+D8 -> 54372 | G8: =C8+E8 -> 5076 | L8: 169000
A9: May | B9: 22800 | C9: 2400 | D9: 38016 | E9: 5136 | F9: =B9+D9 -> 60816 | G9: =C9+E9 -> 7536
A10: June | B10: 22800 | C10: 4800 | D10: 38400 | E10: 4860 | F10: =B10+D10 -> 61200 | G10: =C10+E10 -> 9660
A11: July | B11: 20400 | C11: 0 | D11: 40800 | E11: 3600 | F11: =B11+D11 -> 61200 | G11: =C11+E11 -> 3600
A12: August | B12: 21600 | C12: 2400 | D12: 31524 | E12: 4992 | F12: =B12+D12 -> 53124 | G12: =C12+E12 -> 7392
A13: September | B13: 18000 | C13: 2400 | D13: 32856 | E13: 4128 | F13: =B13+D13 -> 50856 | G13: =C13+E13 -> 6528
A14: October | B14: 19200 | C14: 3600 | D14: 29508 | E14: 3660 | F14: =B14+D14 -> 48708 | G14: =C14+E14 -> 7260
A15: November | B15: 15600 | C15: 2400 | D15: 31656 | E15: 3732 | F15: =B15+D15 -> 47256 | G15: =C15+E15 -> 6132
A16: December | B16: 10800 | C16: 2400 | D16: 19236 | E16: 2976 | F16: =B16+D16 -> 30036 | G16: =C16+E16 -> 5376
A17: Total | B17: =SUM(B5:B16) -> 207180 | C17: =SUM(C5:C16) -> 28284 | D17: =SUM(D5:D16) -> 358236 | E17: =SUM(E5:E16) -> 47712 | F17: =SUM(F5:F16) -> 565416 | G17: =SUM(G5:G16) -> 75996
A18: Annual Electricity Consumption (kWh) | F18: =SUM(F17:G17) -> 641412
A19: Considering the total loss of 11% in the power sector of Bangladesh [1], the energy generated for ULAB has to be more than the energy consumed by ULAB. | F19: =1.11*F18 -> 711967.32
A21: [1] “Annual Report 2021-2022,” Bangladesh Power Development Board (BPDP), Government of Bangladesh, pp. 12-14, Oct. 14, 2021. Accessed on: Sep. 10, 2023. [Online]. Available at: https://bpdb.portal.gov.bd/sites/default/files/files/bpdb.portal.gov.bd/annual_reports/7b792f67_bf50_4b3d_9bef_8f9b568005c9/2022-11-29-05-22-0dea17e09d8a84e72a63312df6b5bdc6.pdf
A23: [2] Charles Thomas, Tessa Tennant, and Jon Rolls, "The GHG Indicator: UNEP Guidelines for Calculating Greenhouse Gas Emissions for Businesses and Non_x0002_Commercial Organisations", United Nations Environment Programme, 2000.
A24: [3] "CO2 Baseline Database for the Indian Power Sector", Government of India Ministry of Power Central Electricity Authority. https://cea.nic.in/wp-content/uploads/baseline/2020/07/user_guide_ver14.pdf
A25: Emission Factors
A26: Source | B26: Avg. GHG (CO2-eq.) Emission Factor from each source (gCO2-eq/kWh) | C26: Combined GHG (CO2-eq.) Emission Factor based on % of each fuel, EFcombined_present
E28: % of power generated from various sources [1]
A29: Gas | B29: 533.17 | C29: =F29*B29 -> 293.5634 | E29: Gas | F29: 0.5506
A30: Coal | B30: 942.33 | C30: =F30*B30 -> 58.801392 | E30: Coal | F30: 0.0624
A31: Oil | B31: 773.8 | C31: =F31*B31 -> 206.68198 | E31: Oil | F31: 0.2671
A32: Solar PV | B32: 65.05 | C32: =F32*B32 -> 0.24719 | E32: Solar PV | F32: 0.0038
A33: Hydro | B33: 8.22 | C33: =F33*B33 -> 0.071514 | E33: Hydro | F33: 0.0087
A34: Wind | B34: 17.63 | C34: =F34*B34 -> 0 | E34: Wind | F34: 0
A35: Nuclear | B35: 12.23 | C35: =F35*B35 -> 0 | E35: Nuclear | F35: 0
A36: Diesel [2] | B36: 266.7 | C36: =F36*B36 -> 4.61391 | E36: Diesel | F36: 0.0173
A37: Power Import [3] | B37: 820 | C37: =F37*B37 -> 73.882 | E37: Power Import | F37: 0.0901
A38: Tot. | C38: =SUM(C29:C37) -> 637.86139
A40: [4] Mirza et al "Assessing the Environmental Consequences of ICEVs and BEVs in Dhaka City via Vehicle Fleet Modeling and Support Vector Regression"

Sheet Scope3
B2: Type of transport | C2: Daily Average Distance Travelled by One Person | D2: Academic Days | E2: Annual Average Distance Travelled by One Person | F2: Number of Personnel | G2: Percentage | H2: CO2 Emission Factor (g/km) | I2: CH4 Emission Factor (g/km) | J2: N2O Emission Factor (g/km) | K2: Annual CO2 Emission by One Person (tCO2/year) | L2: Annual CH4 Emission by One Person (tCO4/year) | M2: Annual N2O Emission by One Person (tN2O/year) | N2: Annual CO2 Emission by All Personnel (tCO2/year) | O2: Annual CH4 Emission by All Personnel (tCO4/year) | P2: Annual N2O Emission by All Personnel (tN2O/year) | R2: Total Distance Travelled Annually by All Personnel in a Cetegory
B3: Walking | C3: 2.51 | D3: 294 | E3: =C3*D$3 -> 737.94 | F3: 41 | G3: =F3/$F$13 -> 0.05408971 | H3: 0 | I3: 0 | J3: 0 | K3: =(H3*E3)/(1000*1000) -> 0 | L3: =(I3*F3)/(1000*1000) -> 0 | M3: =(J3*G3)/(1000*1000) -> 0 | N3: =K3*$F3 -> 0 | O3: =L3*$F3 -> 0 | P3: =M3*$F3 -> 0 | R3: =E3*F3 -> 30255.54 | T3: 0 | U3: =T3*27.9 -> 0 | W3: 0 | X3: =W3*273 -> 0 | Z3: =N3+U3+X3 -> 0 | AA3: =Z3/$Z$13 -> 0
B4: Bicycle | C4: 5.54 | E4: =C4*D$3 -> 1628.76 | F4: 14 | G4: =F4/$F$13 -> 0.018469657 | H4: 0 | I4: 0 | J4: 0 | K4: =(H4*E4)/(1000*1000) -> 0 | L4: =(I4*F4)/(1000*1000) -> 0 | M4: =(J4*G4)/(1000*1000) -> 0 | N4: =K4*$F4 -> 0 | O4: =L4*$F4 -> 0 | P4: =M4*$F4 -> 0 | R4: =E4*F4 -> 22802.64 | T4: 0 | U4: =T4*27.9 -> 0 | W4: 0 | X4: =W4*273 -> 0 | Z4: =N4+U4+X4 -> 0 | AA4: =Z4/$Z$13 -> 0
B5: Rickshaw | C5: 6.08 | E5: =C5*D$3 -> 1787.52 | F5: 198 | G5: =F5/$F$13 -> 0.26121372 | H5: 0 | I5: 0 | J5: 0 | K5: =(H5*E5)/(1000*1000) -> 0 | L5: =(I5*F5)/(1000*1000) -> 0 | M5: =(J5*G5)/(1000*1000) -> 0 | N5: =K5*$F5 -> 0 | O5: =L5*$F5 -> 0 | P5: =M5*$F5 -> 0 | R5: =E5*F5 -> 353928.96 | T5: 0 | U5: =T5*27.9 -> 0 | W5: 0 | X5: =W5*273 -> 0 | Z5: =N5+U5+X5 -> 0 | AA5: =Z5/$Z$13 -> 0
B6: Battery-operated auto-rickshaw | C6: 6.51 | E6: =C6*D$3 -> 1913.94 | F6: 59 | G6: =F6/$F$13 -> 0.077836412 | H6: =J53 -> 50.837553 | K6: =(H6*E6)/(1000*1000) -> 0.097300025 | L6: =(I6*F6)/(1000*1000) -> 0 | M6: =(J6*G6)/(1000*1000) -> 0 | N6: =K6*$F6 -> 5.7407015 | O6: =L6*$F6 -> 0 | P6: =M6*$F6 -> 0 | R6: =E6*F6 -> 112922.46 | T6: 0 | U6: =T6*27.9 -> 0 | W6: 0 | X6: =W6*273 -> 0 | Z6: =N6+U6+X6 -> 5.7407015 | AA6: =Z6/$Z$13 -> 0.031117469
B7: Leguna | C7: 12.15 | E7: =C7*D$3 -> 3572.1 | F7: 14 | G7: =F7/$F$13 -> 0.018469657 | H7: =G43 -> 27.708333 | I7: =H43 -> 0.011666667 | J7: =I43 -> 0.0022333333 | K7: =(H7*E7)/(1000*1000) -> 0.098976938 | L7: =(I7*F7)/(1000*1000) -> 1.6333333e-07 | M7: =(J7*G7)/(1000*1000) -> 4.1248901e-11 | N7: =K7*$F7 -> 1.3856771 | O7: =L7*$F7 -> 2.2866667e-06 | P7: =M7*$F7 -> 5.7748461e-10 | R7: =E7*F7 -> 50009.4 | T7: 2.2866667e-06 | U7: =T7*27.9 -> 6.3798e-05 | W7: 5.7748461e-10 | X7: =W7*273 -> 1.576533e-07 | Z7: =N7+U7+X7 -> 1.3857411 | AA7: =Z7/$Z$13 -> 0.0075114086
B8: Motorcycle | C8: 16.72 | E8: =C8*D$3 -> 4915.68 | F8: 63 | G8: =F8/$F$13 -> 0.083113456 | H8: =G42 -> 40 | I8: =H42 -> 0.08 | J8: =I42 -> 0.00516 | K8: =(H8*E8)/(1000*1000) -> 0.1966272 | L8: =(I8*F8)/(1000*1000) -> 5.04e-06 | M8: =(J8*G8)/(1000*1000) -> 4.2886544e-10 | N8: =K8*$F8 -> 12.387514 | O8: =L8*$F8 -> 0.00031752 | P8: =M8*$F8 -> 2.7018522e-08 | R8: =E8*F8 -> 309687.84 | T8: 0.00031752 | U8: =T8*27.9 -> 0.008858808 | W8: 2.7018522e-08 | X8: =W8*273 -> 7.3760566e-06 | Z8: =N8+U8+X8 -> 12.39638 | AA8: =Z8/$Z$13 -> 0.067194569
B9: Public Bus | C9: 29.02 | E9: =C9*D$3 -> 8531.88 | F9: 117 | G9: =F9/$F$13 -> 0.15435356 | H9: =G39 -> 17.057692 | I9: =H39 -> 0.0011538462 | J9: =I39 -> 0.00051538462 | K9: =(H9*E9)/(1000*1000) -> 0.14553418 | L9: =(I9*F9)/(1000*1000) -> 1.35e-07 | M9: =(J9*G9)/(1000*1000) -> 7.9551451e-11 | N9: =K9*$F9 -> 17.0275 | O9: =L9*$F9 -> 1.5795e-05 | P9: =M9*$F9 -> 9.3075198e-09 | R9: =E9*F9 -> 998229.96 | T9: 1.5795e-05 | U9: =T9*27.9 -> 0.0004406805 | W9: 9.3075198e-09 | X9: =W9*273 -> 2.5409529e-06 | Z9: =N9+U9+X9 -> 17.027943 | AA9: =Z9/$Z$13 -> 0.092299953
B10: CNG Autorickshaw | C10: 15.72 | E10: =C10*D$3 -> 4621.68 | F10: 42 | G10: =F10/$F$13 -> 0.055408971 | H10: =G40 -> 75 | I10: =H40 -> 1.41 | J10: =I40 -> 0.0025 | K10: =(H10*E10)/(1000*1000) -> 0.346626 | L10: =(I10*F10)/(1000*1000) -> 5.922e-05 | M10: =(J10*G10)/(1000*1000) -> 1.3852243e-10 | N10: =K10*$F10 -> 14.558292 | O10: =L10*$F10 -> 0.00248724 | P10: =M10*$F10 -> 5.817942e-09 | R10: =E10*F10 -> 194110.56 | T10: 0.00248724 | U10: =T10*27.9 -> 0.069393996 | W10: 5.817942e-09 | X10: =W10*273 -> 1.5882982e-06 | Z10: =N10+U10+X10 -> 14.627688 | AA10: =Z10/$Z$13 -> 0.079289371
B11: Motorcar | C11: 19.864 | E11: =C11*D$3 -> 5840.016 | F11: 67 | G11: =F11/$F$13 -> 0.088390501 | H11: =G38 -> 280.89701 | I11: =H38 -> 1.0608358 | J11: =I38 -> 0.0017810746 | K11: =(H11*E11)/(1000*1000) -> 1.6404431 | L11: =(I11*F11)/(1000*1000) -> 7.1076e-05 | M11: =(J11*G11)/(1000*1000) -> 1.5743008e-10 | N11: =K11*$F11 -> 109.90969 | O11: =L11*$F11 -> 0.004762092 | P11: =M11*$F11 -> 1.0547815e-08 | R11: =E11*F11 -> 391281.07 | T11: 0.004762092 | U11: =T11*27.9 -> 0.13286237 | W11: 1.0547815e-08 | X11: =W11*273 -> 2.8795536e-06 | Z11: =N11+U11+X11 -> 110.04255 | AA11: =Z11/$Z$13 -> 0.59648557
B12: Multiple Transport | C12: 18.09 | E12: =C12*D$3 -> 5318.46 | F12: 143 | G12: =F12/$F$13 -> 0.18865435 | H12: =(0.2*6*H5+0.8*6*H6+0.2*12.09*H9+0.8*12.09*H7)/18.09 -> 30.58379 | I12: =(0.2*6*I5+0.8*6*I6+0.2*12.09*I9+0.8*12.09*I7)/18.09 -> 0.0063919292 | J12: =(0.2*6*J5+0.8*6*J6+0.2*12.09*J9+0.8*12.09*J7)/18.09 -> 0.001262963 | K12: =(H12*E12)/(1000*1000) -> 0.16265866 | L12: =(I12*F12)/(1000*1000) -> 9.1404588e-07 | M12: =(J12*G12)/(1000*1000) -> 2.3826346e-10 | N12: =K12*$F12 -> 23.260189 | O12: =L12*$F12 -> 0.00013070856 | P12: =M12*$F12 -> 3.4071675e-08 | R12: =E12*F12 -> 760539.78 | T12: 0.00013070856 | U12: =T12*27.9 -> 0.0036467689 | W12: 3.4071675e-08 | X12: =W12*273 -> 9.3015673e-06 | Z12: =N12+U12+X12 -> 23.263845 | AA12: =Z12/$Z$13 -> 0.12610166
C13: =AVERAGE(C3:C12) -> 13.2204 | F13: =SUM(F3:F12) -> 758 | G13: =F13/$F$13 -> 1 | K13: =SUM(K3:K12) -> 2.6881661 | L13: =SUM(L3:L12) -> 0.00013654838 | M13: =SUM(M3:M12) -> 1.0838818e-09 | N13: =SUM(N3:N12) -> 184.26956 | O13: =SUM(O3:O12) -> 0.0077156422 | P13: =SUM(P3:P12) -> 8.7340959e-08 | U13: =SUM(U3:U12) -> 0.21526642 | X13: =SUM(X3:X12) -> 2.3844082e-05 | Z13: =SUM(Z3:Z12) -> 184.48485 | AA13: =Z13/$Z$13 -> 1
K15: Annual CO2 Emission per capita (tCO2/year-person) | L15: Annual CH4 Emission per capita (tCH4/year-person) | M15: Annual N2O Emission per capita (tN2O/year-person) | N15: Annual CO2 Emission in Scope 3 at ULAB (tCO2/year) | O15: Annual CH4 Emission in Scope 3 at ULAB (tCH4/year) | P15: Annual N2O Emission in Scope 3 at ULAB (tN2O/year) | R15: Total Personnal at ULAB
K16: =N13/$F$13 -> 0.24309968 | L16: =O13/$F$13 -> 1.0178948e-05 | M16: =P13/$F$13 -> 1.1522554e-10 | N16: =K16*$R$16 -> 1300.5833 | O16: =L16*$R$16 -> 0.054457369 | P16: =M16*$R$16 -> 6.1645664e-07 | R16: =Total_GHG_Emissions!L4 -> 5350
U18: 0 | V18: =(U18/758)*5350 -> 0 | W18: =V18/2498.79 -> 0
U19: 0 | V19: =(U19/758)*5350 -> 0 | W19: =V19/2498.79 -> 0
U20: 0 | V20: =(U20/758)*5350 -> 0 | W20: =V20/2498.79 -> 0
A21: Vehicle Type | C21: Fuel | D21: No of Vehicles using the fuel | E21: % of Vehicles using the fuel | F21: % of vehicles types | G21: Emission Factors | U21: 5.75 | V21: =(U21/758)*5350 -> 40.583773 | W21: =V21/2498.79 -> 0.01624137
U22: 1.39 | V22: =(U22/758)*5350 -> 9.810686 | W22: =V22/2498.79 -> 0.0039261747
G23: CO2 | H23: CH4 | I23: N2O [X] | J23: Unit | U23: 12.4 | V23: =(U23/758)*5350 -> 87.519789 | W23: =V23/2498.79 -> 0.035024868
A24: Motorcar | B24: Sedan | C24: Gasoline | D24: 32 | E24: =D24/$D$28 -> 0.66666667 | F24: =D28/(D28+D33+D34+D37) -> 0.71641791 | G24: 258 | H24: 0.14 | I24: 0.00087 | J24: gm/km | U24: 17.03 | V24: =(U24/758)*5350 -> 120.19855 | W24: =V24/2498.79 -> 0.048102701
C25: CNG | D25: 6 | E25: =D25/$D$28 -> 0.125 | G25: 237 | H25: 2.53 | I25: 0.0025 | J25: gm/km | L25: [X] Emission Factors for Greenhouse Gas Inventories. Available: https://www.epa.gov/system/files/documents/2024-02/ghg-emission-factors-hub-2024.pdf | U25: 14.63 | V25: =(U25/758)*5350 -> 103.25923 | W25: =V25/2498.79 -> 0.041323695
C26: Diesel | D26: 2 | E26: =D26/$D$28 -> 0.041666667 | G26: 332.5 | H26: 0.14 | I26: 0.0119 | J26: gm/km | U26: 110.05 | V26: =(U26/758)*5350 -> 776.73813 | W26: =V26/2498.79 -> 0.3108457
C27: Gasoline - CNG (this work) | D27: 8 | E27: =D27/$D$28 -> 0.16666667 | G27: =0.2*G24+0.8*G25 -> 241.2 | H27: =0.2*H24+0.8*H25 -> 2.052 | I27: =0.2*I24+0.8*I25 -> 0.002174 | J27: gm/km | U27: 23.27 | V27: =(U27/758)*5350 -> 164.24077 | W27: =V27/2498.79 -> 0.065728118
C28: Weighted Average | D28: =SUM(D24:D27) -> 48 | E28: =D28/$D$28 -> 1 | G28: =SUMPRODUCT(G24:G27, $E$24:$E$27)/SUM($E$24:$E$27) -> 255.67917 | H28: =SUMPRODUCT(H24:H27, $E$24:$E$27)/SUM($E$24:$E$27) -> 0.75741667 | I28: =SUMPRODUCT(I24:I27, $E$24:$E$27)/SUM($E$24:$E$27) -> 0.0017506667 | J28: gm/km
B29: SUV | C29: Gasoline | D29: 5 | E29: =D29/$D$33 -> 0.625 | F29: =D33/(D28+D33+D34+D37) -> 0.11940299 | G29: 331 | H29: 0.14 | I29: 0.00075 | J29: gm/km
C30: CNG | D30: 1 | E30: =D30/$D$33 -> 0.125 | G30: 332.5 | H30: 0.14 | I30: 0.0031 | J30: gm/km
C31: Gasoline-CNG | D31: 2 | E31: =D31/$D$33 -> 0.25 | G31: 304 | H31: 2.53 | I31: =0.5*0.00075+0.5*0.0031 -> 0.001925 | J31: gm/km
C32: Diesel-CNG | E32: =D32/$D$33 -> 0 | G32: 363 | H32: 2.53 | I32: =0.5*0.0133+0.5*0.0031 -> 0.0082 | J32: gm/km
C33: Weighted Average | D33: =SUM(D29:D32) -> 8 | E33: =D33/$D$33 -> 1 | G33: =SUMPRODUCT(G29:G32, $E$29:$E$32)/SUM($E$29:$E$32) -> 324.4375 | H33: =SUMPRODUCT(H29:H32, $E$29:$E$32)/SUM($E$29:$E$32) -> 0.7375 | I33: =SUMPRODUCT(I29:I32, $E$29:$E$32)/SUM($E$29:$E$32) -> 0.0013375 | J33: gm/km | L33: Teachers
B34: Ride-Sharing | C34: CNG | D34: 8 | F34: =D34/(D28+D33+D34+D37) -> 0.11940299 | G34: 237 | H34: 2.53 | I34: 0.0025 | J34: gm/km | L34: Type of transport | M34: Number | N34: %
B35: Minibus | C35: Gasoline | D35: 2 | E35: =D35/(D$37) -> 0.66666667 | F35: =D37/(D28+D33+D34+D37) -> 0.044776119 | G35: 665 | H35: 0.06 | I35: 0.00075 | J35: gm/km | L35: Walking | M35: 0 | N35: =M35/(SUM($M$35:$M$44)) -> 0
C36: CNG | D36: 1 | E36: =D36/(D$37) -> 0.33333333 | G36: 726 | H36: 8.46 | I36: 0.0031 | J36: gm/km | L36: Bicycle | M36: 2 | N36: =M36/(SUM($M$35:$M$44)) -> 0.040816327
C37: Weighted Average | D37: =SUM(D35:D36) -> 3 | E37: =D37/(D$37) -> 1 | G37: =SUMPRODUCT(G35:G36, $E$35:$E$36)/SUM($E$35:$E$36) -> 685.33333 | H37: =SUMPRODUCT(H35:H36, $E$35:$E$36)/SUM($E$35:$E$36) -> 2.86 | I37: =SUMPRODUCT(I35:I36, $E$35:$E$36)/SUM($E$35:$E$36) -> 0.0015333333 | J37: gm/km | L37: Rickshaw | M37: 9 | N37: =M37/(SUM($M$35:$M$44)) -> 0.18367347
C38: Weighted Average | D38: 67 | G38: =$F$24*G28+$F$29*G33+$F$34*G34+$F$35*G37 -> 280.89701 | H38: =$F$24*H28+$F$29*H33+$F$34*H34+$F$35*H37 -> 1.0608358 | I38: =$F$24*I28+$F$29*I33+$F$34*I34+$F$35*I37 -> 0.0017810746 | J38: gm/km | L38: Battery-operated auto-rickshaw | M38: 7 | N38: =M38/(SUM($M$35:$M$44)) -> 0.14285714
A39: Bus | C39: Diesel | E39: 1 | G39: =G45/52 -> 17.057692 | H39: =H45/52 -> 0.0011538462 | I39: =I45/52 -> 0.00051538462 | J39: gm/km | L39: Leguna | M39: 0 | N39: =M39/(SUM($M$35:$M$44)) -> 0
A40: CNG Auto-Rickshaw | C40: CNG | E40: 1 | G40: 75 | H40: 1.41 | I40: 0.0025 | J40: gm/km | L40: Motorcycle | M40: 8 | N40: =M40/(SUM($M$35:$M$44)) -> 0.16326531
A41: Battery-operated Auto-Rickshaw | C41: Electricity | E41: 1 | G41: =J53 -> 50.837553 | J41: gm/km | L41: Public Bus | M41: 1 | N41: =M41/(SUM($M$35:$M$44)) -> 0.020408163
A42: MotorCycle | C42: Gasoline | E42: 1 | G42: 40 | H42: 0.08 | I42: 0.00516 | J42: gm/km | L42: CNG Autorickshaw | M42: 1 | N42: =M42/(SUM($M$35:$M$44)) -> 0.020408163
A43: Leguna | C43: Diesel | E43: 1 | G43: =G46/12 -> 27.708333 | H43: =H46/12 -> 0.011666667 | I43: =I46/12 -> 0.0022333333 | J43: gm/km | L43: Motorcar | M43: 14 | N43: =M43/(SUM($M$35:$M$44)) -> 0.28571429
...

Sheet Total_GHG_Emissions
A1: ULAB GHG Emission Calculations
A2: GHG | B2: Scope 1 | E2: Scope 2 | H2: Scope 3 | K2: Total Carbon Dioxide equivalent (tCO2-eq/year) | L2: Number of students, teachers, and staff | N2: Carbon footprint per capita (tCO2-eq./year)
B3: GHG Emission in 2022 (tCO2/year) | C3: Global Warming Potential (100-year GWP) [1] | D3: Carbon Dioxide equivalent (tCO2-eq/year) | E3: GHG Emission in 2022 (tCO2/year) | F3: Global Warming Potential (GWP) | G3: Carbon Dioxide equivalent (tCO2-eq/year) | H3: GHG Emission in 2022 (tCO2/year) | I3: Global Warming Potential (GWP) | J3: Carbon Dioxide equivalent (tCO2-eq/year)
A4: CO2 | B4: =Scope1!U19 -> 115.60301 | C4: 1 | D4: =B4*C4 -> 115.60301 | G4: =Scope2!I4 -> 454.13646 | H4: =Scope3!N16 -> 1300.5833 | I4: 1 | J4: =H4*I4 -> 1300.5833 | L4: 5350 | N4: =K9/L4 -> 0.40853764
A5: CH4 | B5: =Scope1!V19 -> 0.01784845 | C5: 27.9 | D5: =B5*C5 -> 0.49797174 | H5: =Scope3!O16 -> 0.054457369 | I5: 27.9 | J5: =H5*I5 -> 1.5193606
A6: N2O | B6: =Scope1!W19 -> 0.00081356357 | C6: 273 | D6: =B6*C6 -> 0.22210285 | H6: =Scope3!P16 -> 6.1645664e-07 | I6: 273 | J6: =H6*I6 -> 0.00016829266
A7: HFCs | D7: =Scope1!L46 -> 153.374 | J7: =H7*I7 -> 0
A8: HCFC | D8: =Scope1!O46 -> 159.74 | J8: =H8*I8 -> 0
A9: Total (tCO2-eq/year) | B9: =SUM(D4:D8) -> 429.43709 | E9: =SUM(G4:G8) -> 454.13646 | H9: =SUM(J4:J8) -> 1302.1028 | K9: =B9+E9+H9 -> 2185.6764
A10: Contribution of each scope | B10: =B9/K9 -> 0.19647789 | E10: =E9/K9 -> 0.20777846 | H10: =H9/K9 -> 0.59574365 | K10: =B10+E10+H10 -> 1
A11: Optional Information
A12: Indirect CO2 emission from Water Usage | B12: =Other_GHG_Emissions!L17 -> 1.0257493
A13: [1] The Earth's Energy Budget, Climate Feedbacks and Climate Sensitivity Supplemetary Material (7SM). https://www.ipcc.ch/report/ar6/wg1/downloads/report/IPCC_AR6_WGI_Chapter07_SM.pdf
A16: EPA GHG Emission Factos Hub (2024)
A17: GHG Protocol - Gloal Warming Potential Values, https://ghgprotocol.org/sites/default/files/ghgp/Global-Warming-Potential-Values%20%28Feb%2016%202016%29_1.pdf

Sheet Other_GHG_Emissions
A2: Annual CO2 Emission from Water Usage
A4: Country | B4: CO2 Emission Factor of Water (gCO2/m3) | D4: CO2 Emission Factor of Water (gCO2/Liter) | G4: Bill Month | H4: Previous Reading (Liter) | I4: Present Reading (Liter) | J4: Consumption (Liter) | K4: CO2 Emission Factor of Water (gCO2/liter) | L4: Monthly CO2 Emission (tCO2)
A5: Japan [8] | B5: 376 | D5: =B5/1000 -> 0.376 | G5: 44562 | H5: 83540000 | I5: 83650000 | J5: =I5-H5 -> 110000 | K5: =D9 -> 0.343865 | L5: =(J5*K$5)/(1000*1000) -> 0.03782515
A6: United Kingdom [9] | B6: 340 | D6: =B6/1000 -> 0.34 | G6: 44593 | H6: 83650000 | I6: 83759000 | J6: =I6-H6 -> 109000 | L6: =(J6*K$5)/(1000*1000) -> 0.037481285
A7: Catalan [10] | B7: 395 | D7: =B7/1000 -> 0.395 | G7: 44621 | H7: 83759000 | I7: 83864000 | J7: =I7-H7 -> 105000 | L7: =(J7*K$5)/(1000*1000) -> 0.036105825
A8: Bangladesh [5][11] | B8: 264.46 | D8: =B8/1000 -> 0.26446 | G8: 44652 | H8: 83864000 | I8: 83970000 | J8: =I8-H8 -> 106000 | L8: =(J8*K$5)/(1000*1000) -> 0.03644969
A9: Average | B9: =AVERAGE(B5:B8) -> 343.865 | D9: =B9/1000 -> 0.343865 | G9: 44682 | H9: 83970000 | I9: 84075000 | J9: =I9-H9 -> 105000 | L9: =(J9*K$5)/(1000*1000) -> 0.036105825
G10: 44713 | H10: 84075000 | I10: 84179000 | J10: =I10-H10 -> 104000 | L10: =(J10*K$5)/(1000*1000) -> 0.03576196
A11: [8] Y. Shimizu, S. Dejima, and K. Toyosada, “The CO2 Emission Factor of Water in Japan,” Water, vol. 4, no. 4, pp. 759–769, Sep. 2012, doi: 10.3390/w4040759 | G11: 44743 | H11: 84179000 | I11: 84359000 | J11: =I11-H11 -> 180000 | L11: =(J11*K$5)/(1000*1000) -> 0.0618957
G12: 44774 | J12: =I12-H12 -> 0 | L12: =(J12*K$5)/(1000*1000) -> 0
A13: [9] Measuring scope 3 carbon emissions - water and waste. https://dera.ioe.ac.uk/id/eprint/13480/1/water.pdf | G13: 44805 | H13: 0 | I13: 20000 | J13: =I13-H13 -> 20000 | L13: =(J13*K$5)/(1000*1000) -> 0.0068773
G14: 44835 | H14: 20000 | I14: 517000 | J14: =I14-H14 -> 497000 | L14: =(J14*K$5)/(1000*1000) -> 0.17090091
A15: [10] Practical Guide for Calculating Greenhouse Gas (GHG) Emissions. https://canviclimatic.gencat.cat/web/.content/04_ACTUA/Com_calcular_emissions_GEH/guia_de_calcul_demissions_de_co2/190301_Practical-guide-calculating-GHG-emissions_OCCC.pdf | G15: 44866 | H15: 517000 | I15: 1240000 | J15: =I15-H15 -> 723000 | L15: =(J15*K$5)/(1000*1000) -> 0.2486144
G16: 44896 | H16: 1240000 | I16: 2164000 | J16: =I16-H16 -> 924000 | L16: =(J16*K$5)/(1000*1000) -> 0.31773126
G17: Annual Indirect CO2 Emission (tCO2) | L17: =SUM(L5:L16) -> 1.0257493
A18: [11] Climate Change Assessment. https://www.adb.org/sites/default/files/linked-documents/42173-016-cca.pdf
A20: 0.406 kWh/m3 [11] * 651.38 gCO2/kWh [5]
